2024-02-24 19:36:57,431 Getting artifact
[34m[1mwandb[39m[22m: [32m[41mERROR[39m[49m Unable to fetch artifact with name samuel-haddad/exercise_1/zen_of_python:v1
Traceback (most recent call last):
  File "/home/haddadsm/anaconda3/lib/python3.11/site-packages/wandb/apis/normalize.py", line 41, in wrapper
    return func(*args, **kwargs)
           ^^^^^^^^^^^^^^^^^^^^^
  File "/home/haddadsm/anaconda3/lib/python3.11/site-packages/wandb/apis/public/api.py", line 961, in artifact
    artifact = wandb.Artifact._from_name(
               ^^^^^^^^^^^^^^^^^^^^^^^^^^
  File "/home/haddadsm/anaconda3/lib/python3.11/site-packages/wandb/sdk/artifacts/artifact.py", line 254, in _from_name
    raise ValueError(
ValueError: Unable to fetch artifact with name samuel-haddad/exercise_1/zen_of_python:v1
During handling of the above exception, another exception occurred:
Traceback (most recent call last):
  File "/mnt/d/OneDrive/Desktop/samuel-haddad/cd0581-building-a-reproducible-model-workflow-exercises/lesson-1-machine-learning-pipelines/exercises/exercise_1/solution/use_artifact.py", line 41, in <module>
    go(args)
  File "/mnt/d/OneDrive/Desktop/samuel-haddad/cd0581-building-a-reproducible-model-workflow-exercises/lesson-1-machine-learning-pipelines/exercises/exercise_1/solution/use_artifact.py", line 18, in go
    artifact = run.use_artifact(args.artifact_name)
               ^^^^^^^^^^^^^^^^^^^^^^^^^^^^^^^^^^^^
  File "/home/haddadsm/anaconda3/lib/python3.11/site-packages/wandb/sdk/wandb_run.py", line 371, in wrapper_fn
    return func(self, *args, **kwargs)
           ^^^^^^^^^^^^^^^^^^^^^^^^^^^
  File "/home/haddadsm/anaconda3/lib/python3.11/site-packages/wandb/sdk/wandb_run.py", line 361, in wrapper
    return func(self, *args, **kwargs)
           ^^^^^^^^^^^^^^^^^^^^^^^^^^^
  File "/home/haddadsm/anaconda3/lib/python3.11/site-packages/wandb/sdk/wandb_run.py", line 2795, in use_artifact
    artifact = public_api.artifact(type=type, name=name)
               ^^^^^^^^^^^^^^^^^^^^^^^^^^^^^^^^^^^^^^^^^
  File "/home/haddadsm/anaconda3/lib/python3.11/site-packages/wandb/apis/normalize.py", line 87, in wrapper
    raise CommError(message, err).with_traceback(sys.exc_info()[2])
  File "/home/haddadsm/anaconda3/lib/python3.11/site-packages/wandb/apis/normalize.py", line 41, in wrapper
    return func(*args, **kwargs)
           ^^^^^^^^^^^^^^^^^^^^^
  File "/home/haddadsm/anaconda3/lib/python3.11/site-packages/wandb/apis/public/api.py", line 961, in artifact
    artifact = wandb.Artifact._from_name(
               ^^^^^^^^^^^^^^^^^^^^^^^^^^
  File "/home/haddadsm/anaconda3/lib/python3.11/site-packages/wandb/sdk/artifacts/artifact.py", line 254, in _from_name
    raise ValueError(
wandb.errors.CommError: Unable to fetch artifact with name samuel-haddad/exercise_1/zen_of_python:v1